Workbook

Sheet Sales_Transactions
A1: OrderID | B1: CustomerID | C1: ProductID | D1: OrderDate | E1: Quantity | F1: UnitPrice | G1: Discount | H1: Region | I1: Salesperson | J1: DeliveryStatus | K1: PaymentMethod | L1: ProfitMargin | M1: Total_cost | N1: COST PRICE | O1: Profit | P1: ProductName | Q1: Category | R1: Supplier | S1: CostPrice
A2: 1001 | B2: C001 | C2: P005 | D2: 45306 | E2: 3 | F2: 49.99 | G2: 0.05 | H2: North | I2: Alice | J2: Delivered | K2: Credit Card | L2: 0.25 | M2: =SUM(E2*F2*(1-G2)) -> 142.4715 | N2: =VLOOKUP(C2, Product_Details!$A$2:$E$11, 5, FALSE) * E2 -> 120 | O2: =M2-N2 -> 22.4715 | P2: =VLOOKUP(C2,Product_Details!$A$2:$E$11,2,FALSE) -> Mechanical Keyboard | Q2: =VLOOKUP(C2,Product_Details!$A$2:$E$11,3,FALSE) -> Electronics | R2: =VLOOKUP(C2,Product_Details!$A$2:$E$11,4,FALSE) -> TechCorp | S2: =VLOOKUP(C2,Product_Details!$A$2:$E$11,5,FALSE) -> 40
A3: 1002 | B3: C002 | C3: P002 | D3: 45307 | E3: 1 | F3: 199.99 | G3: 0 | H3: South | I3: Bob | J3: Pending | K3: Bank Transfer | L3: 0.18 | M3: =SUM(E3*F3*(1-G3)) -> 199.99 | N3: =VLOOKUP(C3, Product_Details!$A$2:$E$11, 5, FALSE) * E3 -> 150 | O3: =M3-N3 -> 49.99 | P3: =VLOOKUP(C3,Product_Details!$A$2:$E$11,2,FALSE) -> Wireless Mouse | Q3: =VLOOKUP(C3,Product_Details!$A$2:$E$11,3,FALSE) -> Electronics | R3: =VLOOKUP(C3,Product_Details!$A$2:$E$11,4,FALSE) -> TechCorp | S3: =VLOOKUP(C3,Product_Details!$A$2:$E$11,5,FALSE) -> 150
A4: 1003 | B4: C003 | C4: P008 | D4: 45308 | E4: 5 | F4: 19.99 | G4: 0.1 | H4: East | I4: Carol | J4: Delivered | K4: Cash | L4: 0.3 | M4: =SUM(E4*F4*(1-G4)) -> 89.955 | N4: =VLOOKUP(C4, Product_Details!$A$2:$E$11, 5, FALSE) * E4 -> 75 | O4: =M4-N4 -> 14.955 | P4: =VLOOKUP(C4,Product_Details!$A$2:$E$11,2,FALSE) -> Pen Set Premium | Q4: =VLOOKUP(C4,Product_Details!$A$2:$E$11,3,FALSE) -> Office Supplies | R4: =VLOOKUP(C4,Product_Details!$A$2:$E$11,4,FALSE) -> StationeryPlus | S4: =VLOOKUP(C4,Product_Details!$A$2:$E$11,5,FALSE) -> 15
A5: 1004 | B5: C004 | C5: P001 | D5: 45309 | E5: 2 | F5: 99.99 | G5: 0 | H5: West | I5: David | J5: Delivered | K5: Credit Card | L5: 0.22 | M5: =SUM(E5*F5*(1-G5)) -> 199.98 | N5: =VLOOKUP(C5, Product_Details!$A$2:$E$11, 5, FALSE) * E5 -> 1600 | O5: =M5-N5 -> -1400.02 | P5: =VLOOKUP(C5,Product_Details!$A$2:$E$11,2,FALSE) -> Laptop Pro | Q5: =VLOOKUP(C5,Product_Details!$A$2:$E$11,3,FALSE) -> Electronics | R5: =VLOOKUP(C5,Product_Details!$A$2:$E$11,4,FALSE) -> TechCorp | S5: =VLOOKUP(C5,Product_Details!$A$2:$E$11,5,FALSE) -> 800
A6: 1005 | B6: C001 | C6: P003 | D6: 45310 | E6: 1 | F6: 299.99 | G6: 0.05 | H6: North | I6: Alice | J6: Delivered | K6: Credit Card | L6: 0.15 | M6: =SUM(E6*F6*(1-G6)) -> 284.9905 | N6: =VLOOKUP(C6, Product_Details!$A$2:$E$11, 5, FALSE) * E6 -> 250 | O6: =M6-N6 -> 34.9905 | P6: =VLOOKUP(C6,Product_Details!$A$2:$E$11,2,FALSE) -> Ergonomic Chair | Q6: =VLOOKUP(C6,Product_Details!$A$2:$E$11,3,FALSE) -> Office Furniture | R6: =VLOOKUP(C6,Product_Details!$A$2:$E$11,4,FALSE) -> FurniMart | S6: =VLOOKUP(C6,Product_Details!$A$2:$E$11,5,FALSE) -> 250
A7: 1006 | B7: C005 | C7: P006 | D7: 45311 | E7: 4 | F7: 79.99 | G7: 0 | H7: South | I7: Bob | J7: Delivered | K7: Debit Card | L7: 0.28 | M7: =SUM(E7*F7*(1-G7)) -> 319.96 | N7: =VLOOKUP(C7, Product_Details!$A$2:$E$11, 5, FALSE) * E7 -> 240 | O7: =M7-N7 -> 79.96 | P7: =VLOOKUP(C7,Product_Details!$A$2:$E$11,2,FALSE) -> Desk Lamp | Q7: =VLOOKUP(C7,Product_Details!$A$2:$E$11,3,FALSE) -> Office Furniture | R7: =VLOOKUP(C7,Product_Details!$A$2:$E$11,4,FALSE) -> LightCo | S7: =VLOOKUP(C7,Product_Details!$A$2:$E$11,5,FALSE) -> 60
A8: 1007 | B8: C006 | C8: P009 | D8: 45312 | E8: 2 | F8: 39.99 | G8: 0.15 | H8: East | I8: Carol | J8: Pending | K8: Cash | L8: 0.32 | M8: =SUM(E8*F8*(1-G8)) -> 67.983 | N8: =VLOOKUP(C8, Product_Details!$A$2:$E$11, 5, FALSE) * E8 -> 60 | O8: =M8-N8 -> 7.983 | P8: =VLOOKUP(C8,Product_Details!$A$2:$E$11,2,FALSE) -> Notebook (A4) | Q8: =VLOOKUP(C8,Product_Details!$A$2:$E$11,3,FALSE) -> Office Supplies | R8: =VLOOKUP(C8,Product_Details!$A$2:$E$11,4,FALSE) -> StationeryPlus | S8: =VLOOKUP(C8,Product_Details!$A$2:$E$11,5,FALSE) -> 30
A9: 1008 | B9: C007 | C9: P004 | D9: 45313 | E9: 3 | F9: 149.99 | G9: 0 | H9: West | I9: David | J9: Delivered | K9: Credit Card | L9: 0.2 | M9: =SUM(E9*F9*(1-G9)) -> 449.97 | N9: =VLOOKUP(C9, Product_Details!$A$2:$E$11, 5, FALSE) * E9 -> 360 | O9: =M9-N9 -> 89.97 | P9: =VLOOKUP(C9,Product_Details!$A$2:$E$11,2,FALSE) -> Noise-Cancelling Headphones | Q9: =VLOOKUP(C9,Product_Details!$A$2:$E$11,3,FALSE) -> Electronics | R9: =VLOOKUP(C9,Product_Details!$A$2:$E$11,4,FALSE) -> AudioMax | S9: =VLOOKUP(C9,Product_Details!$A$2:$E$11,5,FALSE) -> 120
A10: 1009 | B10: C002 | C10: P007 | D10: 45314 | E10: 1 | F10: 89.99 | G10: 0.1 | H10: South | I10: Bob | J10: Delivered | K10: Bank Transfer | L10: 0.26 | M10: =SUM(E10*F10*(1-G10)) -> 80.991 | N10: =VLOOKUP(C10, Product_Details!$A$2:$E$11, 5, FALSE) * E10 -> 70 | O10: =M10-N10 -> 10.991 | P10: =VLOOKUP(C10,Product_Details!$A$2:$E$11,2,FALSE) -> Webcam HD | Q10: =VLOOKUP(C10,Product_Details!$A$2:$E$11,3,FALSE) -> Electronics | R10: =VLOOKUP(C10,Product_Details!$A$2:$E$11,4,FALSE) -> AudioMax | S10: =VLOOKUP(C10,Product_Details!$A$2:$E$11,5,FALSE) -> 70
A11: 1010 | B11: C008 | C11: P001 | D11: 45315 | E11: 5 | F11: 99.99 | G11: 0.05 | H11: North | I11: Alice | J11: Delivered | K11: Credit Card | L11: 0.22 | M11: =SUM(E11*F11*(1-G11)) -> 474.9525 | N11: =VLOOKUP(C11, Product_Details!$A$2:$E$11, 5, FALSE) * E11 -> 4000 | O11: =M11-N11 -> -3525.0475 | P11: =VLOOKUP(C11,Product_Details!$A$2:$E$11,2,FALSE) -> Laptop Pro | Q11: =VLOOKUP(C11,Product_Details!$A$2:$E$11,3,FALSE) -> Electronics | R11: =VLOOKUP(C11,Product_Details!$A$2:$E$11,4,FALSE) -> TechCorp | S11: =VLOOKUP(C11,Product_Details!$A$2:$E$11,5,FALSE) -> 800
A12: 1011 | B12: C003 | C12: P005 | D12: 45316 | E12: 2 | F12: 49.99 | G12: 0 | H12: East | I12: Carol | J12: Pending | K12: Cash | L12: 0.25 | M12: =SUM(E12*F12*(1-G12)) -> 99.98 | N12: =VLOOKUP(C12, Product_Details!$A$2:$E$11, 5, FALSE) * E12 -> 80 | O12: =M12-N12 -> 19.98 | P12: =VLOOKUP(C12,Product_Details!$A$2:$E$11,2,FALSE) -> Mechanical Keyboard | Q12: =VLOOKUP(C12,Product_Details!$A$2:$E$11,3,FALSE) -> Electronics | R12: =VLOOKUP(C12,Product_Details!$A$2:$E$11,4,FALSE) -> TechCorp | S12: =VLOOKUP(C12,Product_Details!$A$2:$E$11,5,FALSE) -> 40
A13: 1012 | B13: C009 | C13: P002 | D13: 45323 | E13: 1 | F13: 199.99 | G13: 0 | H13: West | I13: David | J13: Delivered | K13: Debit Card | L13: 0.18 | M13: =SUM(E13*F13*(1-G13)) -> 199.99 | N13: =VLOOKUP(C13, Product_Details!$A$2:$E$11, 5, FALSE) * E13 -> 150 | O13: =M13-N13 -> 49.99 | P13: =VLOOKUP(C13,Product_Details!$A$2:$E$11,2,FALSE) -> Wireless Mouse | Q13: =VLOOKUP(C13,Product_Details!$A$2:$E$11,3,FALSE) -> Electronics | R13: =VLOOKUP(C13,Product_Details!$A$2:$E$11,4,FALSE) -> TechCorp | S13: =VLOOKUP(C13,Product_Details!$A$2:$E$11,5,FALSE) -> 150
... A26: 1025 | B26: C004 | C26: P006 | D26: 45336 | E26: 1 | F26: 79.99 | G26: 0 | H26: North | I26: Alice | J26: Delivered | K26: Debit Card | L26: 0.28 | M26: =SUM(E26*F26*(1-G26)) -> 79.99 | N26: =VLOOKUP(C26, Product_Details!$A$2:$E$11, 5, FALSE) * E26 -> 60 | O26: =M26-N26 -> 19.99 | P26: =VLOOKUP(C26,Product_Details!$A$2:$E$11,2,FALSE) -> Desk Lamp | Q26: =VLOOKUP(C26,Product_Details!$A$2:$E$11,3,FALSE) -> Office Furniture | R26: =VLOOKUP(C26,Product_Details!$A$2:$E$11,4,FALSE) -> LightCo | S26: =VLOOKUP(C26,Product_Details!$A$2:$E$11,5,FALSE) -> 60
M27: =SUM(M2:M26) -> 5848.4445
M28: =AVERAGE(M2:M26) -> 233.93778
C30: {=_xlfn.UNIQUE(B2:B26)} -> C001 | D30: Row Labels | E30: Count of PaymentMethod | G30: Row Labels | H30: Count of DeliveryStatus
C31: C002 | D31: Bank Transfer | E31: 5 | G31: Delivered | H31: 19 | I31: =COUNTIF(J2:J26,"=Delivered") -> 19
C32: C003 | D32: Cash | E32: 5 | G32: Pending | H32: 6 | I32: =COUNTIF(J2:J26,"=Pending") -> 6
C33: C004 | D33: Credit Card | E33: 11 | G33: Grand Total | H33: 25
C34: C005 | D34: Debit Card | E34: 4
C35: C006 | D35: Grand Total | E35: 25
C36: C007
C37: C008
C38: C009
C39: C010
C40: =COUNTA(_xlfn.ANCHORARRAY(C30)) -> 10
I41: Row Labels | J41: Sum of Profit
A42: Row Labels | B42: Sum of Profit | I42: Wireless Mouse | J42: 219.9515
A43: East | B43: -3457.148 | I43: Ergonomic Chair | J43: 164.9445
A44: North | B44: -3290.1635 | I44: Desk Lamp | J44: 139.93
A45: South | B45: 230.881 | I45: Noise-Cancelling Headphones | J45: 112.4605
A46: West | B46: -1135.125 | I46: Webcam HD | J46: 50.971
A47: Grand Total | B47: -7651.5555 | I47: Grand Total | J47: 688.2575
I51: Row Labels | J51: Average of ProfitMargin
I52: Desk Lamp | J52: 0.28
I53: Ergonomic Chair | J53: 0.15
I54: Laptop Pro | J54: 0.22
I55: Mechanical Keyboard | J55: 0.25
I56: Noise-Cancelling Headphones | J56: 0.2
...

Sheet Product_Details
A1: ProductID | B1: ProductName | C1: Category | D1: Supplier | E1: CostPrice | F1: RetailPrice
A2: P001 | B2: Laptop Pro | C2: Electronics | D2: TechCorp | E2: 800 | F2: 999.99
A3: P002 | B3: Wireless Mouse | C3: Electronics | D3: TechCorp | E3: 150 | F3: 199.99
A4: P003 | B4: Ergonomic Chair | C4: Office Furniture | D4: FurniMart | E4: 250 | F4: 299.99
A5: P004 | B5: Noise-Cancelling Headphones | C5: Electronics | D5: AudioMax | E5: 120 | F5: 149.99
A6: P005 | B6: Mechanical Keyboard | C6: Electronics | D6: TechCorp | E6: 40 | F6: 49.99
A7: P006 | B7: Desk Lamp | C7: Office Furniture | D7: LightCo | E7: 60 | F7: 79.99
A8: P007 | B8: Webcam HD | C8: Electronics | D8: AudioMax | E8: 70 | F8: 89.99
A9: P008 | B9: Pen Set Premium | C9: Office Supplies | D9: StationeryPlus | E9: 15 | F9: 19.99
A10: P009 | B10: Notebook (A4) | C10: Office Supplies | D10: StationeryPlus | E10: 30 | F10: 39.99
A11: P010 | B11: External SSD | C11: Electronics | D11: TechCorp | E11: 100 | F11: 129.99

Sheet Case Study
A1: Scenario: You are a Junior Data Analyst at "OmniMarket," a growing e-commerce company that sells a variety of products across different categories. The company has been operating for a few months, and management is eager to understand their sales performance, identify key trends, and make data-driven decisions to optimize operations and marketing strategies. The Sales_Transactions sheet contains records of every order, including quantities, prices, regions, and salespersons. The Product_Details sheet provides static information about each product, such as its name, category, and cost. Your task is to analyze this data to provide insights to OmniMarket's management team. They are particularly interested in understanding: Overall sales performance and profitability. Performance of different product categories and individual products. Geographical sales distribution. Effectiveness of their sales team. Efficiency of their delivery process. Use the provided data to answer the following questions, presenting your findings clearly, ideally with appropriate charts and pivot tables where specified.
A16: Section 1: Basic Calculations & Data Understanding
A18: Total Revenue: Calculate the total revenue generated from all sales. (Hint: Quantity * UnitPrice * (1 - Discount) for each order line item, then sum).
A19: Net Profit: Calculate the total net profit. (Hint: You'll need to join data from both sheets. Net Profit per Item = (UnitPrice * (1 - Discount) - CostPrice) * Quantity. Sum this for all items).
A20: Average Order Value: What is the average value of an order (after discount)?
A21: Number of Unique Customers: How many unique customers have placed an order? | I21: 10
A22: Most Frequent Payment Method: Which payment method is used most frequently by customers? | I22: Credit card
A23: Orders by Delivery Status: What is the count of orders for each DeliveryStatus (Delivered, Pending)? | I23: done 19,6
A25: Section 2: Lookups & Data Combination
A27: Add Product Details to Sales: In the Sales_Transactions sheet, add new columns for ProductName, Category, Supplier, CostPrice, and RetailPrice by using ProductID to lookup information from the Product_Details sheet.
A28: Calculate Total_Sale_Price: For each transaction in Sales_Transactions, calculate the Total_Sale_Price after applying the discount (Quantity * UnitPrice * (1 - Discount)).
A29: Calculate Total_Cost_Price: For each transaction, calculate the Total_Cost_Price (Quantity * CostPrice).
A30: Calculate Transaction_Profit: For each transaction, calculate the Transaction_Profit (Total_Sale_Price - Total_Cost_Price).
A32: Section 3: Pivot Tables & Summarization
A34: Sales by Region: Create a pivot table showing the Total Revenue for each Region. Visualize this with a Column Chart. | J34: Done
A35: Sales by Salesperson: Create a pivot table showing the Total Revenue generated by each Salesperson. Who is the top performer by revenue? | K35: > Bob
A36: Profitability by Category: Create a pivot table to analyze the Total_Profit for each Category. Which category is most profitable? | K36: office
A37: Monthly Sales Trend: Create a pivot table to show the Total Revenue broken down by month (using OrderDate). How has sales performance changed month-over-month? Visualize this with a Line Chart. | P37: done
A38: Top 5 Products by Revenue: Using a pivot table or sorting, identify the top 5 ProductName by Total Revenue. | I38: Done
A39: Average Profit Margin by Product: Calculate the average ProfitMargin for each ProductName. | I39: Done
A40: Pending Orders by Region: Create a pivot table showing the count of Pending orders for each Region. | I40: to check
A42: Section 4: Advanced Analysis & Visualization
A44: Discount Impact: Analyze the average Discount applied across all orders. Are there any patterns in discount usage (e.g., by region, product category)? (This might require a pivot table or filtering).
A45: Customer Spending Habits: Identify the CustomerID who has spent the most money (total revenue).
A46: Visualizing Delivery Status: Create a chart (e.g., Donut or Pie Chart) to visualize the proportion of Delivered vs. Pending orders.
