Workbook

Sheet sales
A1: OrderID | B1: OrderDate | C1: CustomerID | D1: CustomerName | E1: Region | F1: ProductCategory | G1: ProductName | H1: UnitsSold | I1: UnitPrice | J1: Discount | K1: Salesperson | L1: PaymentMethod | M1: NeT Sales | N1: Order_Month | O1: Order_Year | P1: CustomerLoyaltyStatus | Q1: CustomerCity | R1: Order_Quarter
A2: GM-0001 | B2: 44941 | C2: CUST-001 | D2: Sarah Chen | E2: North | F2: Electronics | G2: Laptop Pro | H2: 2 | I2: 850 | J2: 0.05 | K2: Alice | L2: Credit Card | M2: =H2 * I2 * (1 - J2) -> 1615 | N2: =TEXT(B2,"mmmm") -> January | O2: =TEXT(B2,"yyyy") -> 2023 | P2: =VLOOKUP(C2,customer!$A$1:$F$16,6,FALSE) -> Platinum | Q2: =VLOOKUP(C2,customer!$A$1:$F$16,4,FALSE) -> Springfield | R2: =CONCATENATE("Q",ROUNDUP(MONTH(B2)/3,0)," - ",YEAR(B2)) -> Q1 - 2023
A3: GM-0002 | B3: 44944 | C3: CUST-003 | D3: David Lee | E3: South | F3: Apparel | G3: T-Shirt (Large) | H3: 5 | I3: 25 | J3: 0 | K3: Bob | L3: Cash | M3: =H3 * I3 * (1 - J3) -> 125 | N3: =TEXT(B3,"mmmm") -> January | O3: =TEXT(B3,"yyyy") -> 2023 | P3: =VLOOKUP(C3,customer!$A$1:$F$16,6,FALSE) -> Silver | Q3: =VLOOKUP(C3,customer!$A$1:$F$16,4,FALSE) -> Lakeside | R3: =CONCATENATE("Q",ROUNDUP(MONTH(B3)/3,0)," - ",YEAR(B3)) -> Q1 - 2023
A4: GM-0003 | B4: 44946 | C4: CUST-002 | D4: Emily White | E4: East | F4: Home Goods | G4: Coffee Maker | H4: 1 | I4: 120 | J4: 0.1 | K4: Charlie | L4: UPI | M4: =H4 * I4 * (1 - J4) -> 108 | N4: =TEXT(B4,"mmmm") -> January | O4: =TEXT(B4,"yyyy") -> 2023 | P4: =VLOOKUP(C4,customer!$A$1:$F$16,6,FALSE) -> Gold | Q4: =VLOOKUP(C4,customer!$A$1:$F$16,4,FALSE) -> Rivertown | R4: =CONCATENATE("Q",ROUNDUP(MONTH(B4)/3,0)," - ",YEAR(B4)) -> Q1 - 2023
A5: GM-0004 | B5: 44958 | C5: CUST-001 | D5: Sarah Chen | E5: North | F5: Books | G5: Sci-Fi Novel | H5: 3 | I5: 15 | J5: 0 | K5: Alice | L5: Bank Transfer | M5: =H5 * I5 * (1 - J5) -> 45 | N5: =TEXT(B5,"mmmm") -> February | O5: =TEXT(B5,"yyyy") -> 2023 | P5: =VLOOKUP(C5,customer!$A$1:$F$16,6,FALSE) -> Platinum | Q5: =VLOOKUP(C5,customer!$A$1:$F$16,4,FALSE) -> Springfield | R5: =CONCATENATE("Q",ROUNDUP(MONTH(B5)/3,0)," - ",YEAR(B5)) -> Q1 - 2023
A6: GM-0005 | B6: 44962 | C6: CUST-004 | D6: Michael Brown | E6: West | F6: Food | G6: Organic Snacks | H6: 10 | I6: 5 | J6: 0 | K6: David | L6: Credit Card | M6: =H6 * I6 * (1 - J6) -> 50 | N6: =TEXT(B6,"mmmm") -> February | O6: =TEXT(B6,"yyyy") -> 2023 | P6: =VLOOKUP(C6,customer!$A$1:$F$16,6,FALSE) -> Bronze | Q6: =VLOOKUP(C6,customer!$A$1:$F$16,4,FALSE) -> Hillside | R6: =CONCATENATE("Q",ROUNDUP(MONTH(B6)/3,0)," - ",YEAR(B6)) -> Q1 - 2023
A7: GM-0006 | B7: 44967 | C7: CUST-005 | D7: Jessica Green | E7: Central | F7: Electronics | G7: Wireless Earbuds | H7: 1 | I7: 99 | J7: 0.05 | K7: Eve | L7: Cash | M7: =H7 * I7 * (1 - J7) -> 94.05 | N7: =TEXT(B7,"mmmm") -> February | O7: =TEXT(B7,"yyyy") -> 2023 | P7: =VLOOKUP(C7,customer!$A$1:$F$16,6,FALSE) -> Gold | Q7: =VLOOKUP(C7,customer!$A$1:$F$16,4,FALSE) -> Centralia | R7: =CONCATENATE("Q",ROUNDUP(MONTH(B7)/3,0)," - ",YEAR(B7)) -> Q1 - 2023
A8: GM-0007 | B8: 44969 | C8: CUST-003 | D8: David Lee | E8: South | F8: Apparel | G8: Jeans (Size 32) | H8: 2 | I8: 60 | J8: 0 | K8: Bob | L8: UPI | M8: =H8 * I8 * (1 - J8) -> 120 | N8: =TEXT(B8,"mmmm") -> February | O8: =TEXT(B8,"yyyy") -> 2023 | P8: =VLOOKUP(C8,customer!$A$1:$F$16,6,FALSE) -> Silver | Q8: =VLOOKUP(C8,customer!$A$1:$F$16,4,FALSE) -> Lakeside | R8: =CONCATENATE("Q",ROUNDUP(MONTH(B8)/3,0)," - ",YEAR(B8)) -> Q1 - 2023
A9: GM-0008 | B9: 44986 | C9: CUST-002 | D9: Emily White | E9: East | F9: Home Goods | G9: Blender | H9: 1 | I9: 70 | J9: 0.15 | K9: Charlie | L9: Credit Card | M9: =H9 * I9 * (1 - J9) -> 59.5 | N9: =TEXT(B9,"mmmm") -> March | O9: =TEXT(B9,"yyyy") -> 2023 | P9: =VLOOKUP(C9,customer!$A$1:$F$16,6,FALSE) -> Gold | Q9: =VLOOKUP(C9,customer!$A$1:$F$16,4,FALSE) -> Rivertown | R9: =CONCATENATE("Q",ROUNDUP(MONTH(B9)/3,0)," - ",YEAR(B9)) -> Q1 - 2023
A10: GM-0009 | B10: 44990 | C10: CUST-004 | D10: Michael Brown | E10: West | F10: Books | G10: History Textbook | H10: 1 | I10: 40 | J10: 0 | K10: David | L10: Bank Transfer | M10: =H10 * I10 * (1 - J10) -> 40 | N10: =TEXT(B10,"mmmm") -> March | O10: =TEXT(B10,"yyyy") -> 2023 | P10: =VLOOKUP(C10,customer!$A$1:$F$16,6,FALSE) -> Bronze | Q10: =VLOOKUP(C10,customer!$A$1:$F$16,4,FALSE) -> Hillside | R10: =CONCATENATE("Q",ROUNDUP(MONTH(B10)/3,0)," - ",YEAR(B10)) -> Q1 - 2023
A11: GM-0010 | B11: 44993 | C11: CUST-001 | D11: Sarah Chen | E11: North | F11: Electronics | G11: Smartwatch | H11: 1 | I11: 250 | J11: 0 | K11: Alice | L11: UPI | M11: =H11 * I11 * (1 - J11) -> 250 | N11: =TEXT(B11,"mmmm") -> March | O11: =TEXT(B11,"yyyy") -> 2023 | P11: =VLOOKUP(C11,customer!$A$1:$F$16,6,FALSE) -> Platinum | Q11: =VLOOKUP(C11,customer!$A$1:$F$16,4,FALSE) -> Springfield | R11: =CONCATENATE("Q",ROUNDUP(MONTH(B11)/3,0)," - ",YEAR(B11)) -> Q1 - 2023
A12: GM-0011 | B12: 44995 | C12: CUST-006 | D12: Chris Taylor | E12: South | F12: Food | G12: Gourmet Coffee | H12: 2 | I12: 20 | J12: 0 | K12: Bob | L12: Cash | M12: =H12 * I12 * (1 - J12) -> 40 | N12: =TEXT(B12,"mmmm") -> March | O12: =TEXT(B12,"yyyy") -> 2023 | P12: =VLOOKUP(C12,customer!$A$1:$F$16,6,FALSE) -> Silver | Q12: =VLOOKUP(C12,customer!$A$1:$F$16,4,FALSE) -> Oceanview | R12: =CONCATENATE("Q",ROUNDUP(MONTH(B12)/3,0)," - ",YEAR(B12)) -> Q1 - 2023
A13: GM-0012 | B13: 45000 | C13: CUST-007 | D13: Olivia Davis | E13: East | F13: Apparel | G13: Winter Coat | H13: 1 | I13: 150 | J13: 0.1 | K13: Charlie | L13: Credit Card | M13: =H13 * I13 * (1 - J13) -> 135 | N13: =TEXT(B13,"mmmm") -> March | O13: =TEXT(B13,"yyyy") -> 2023 | P13: =VLOOKUP(C13,customer!$A$1:$F$16,6,FALSE) -> Bronze | Q13: =VLOOKUP(C13,customer!$A$1:$F$16,4,FALSE) -> Metroville | R13: =CONCATENATE("Q",ROUNDUP(MONTH(B13)/3,0)," - ",YEAR(B13)) -> Q1 - 2023
... A16: GM-0015 | B16: 45026 | C16: CUST-006 | D16: Chris Taylor | E16: South | F16: Books | G16: Self-Help Guide | H16: 2 | I16: 18 | J16: 0 | K16: Bob | L16: UPI | M16: =H16 * I16 * (1 - J16) -> 36 | N16: =TEXT(B16,"mmmm") -> April | O16: =TEXT(B16,"yyyy") -> 2023 | P16: =VLOOKUP(C16,customer!$A$1:$F$16,6,FALSE) -> Silver | Q16: =VLOOKUP(C16,customer!$A$1:$F$16,4,FALSE) -> Oceanview | R16: =CONCATENATE("Q",ROUNDUP(MONTH(B16)/3,0)," - ",YEAR(B16)) -> Q2 - 2023
A17: GM-0016 | B17: 44967 | C17: CUST-011 | D17: =VLOOKUP(C17,customer!$A$1:$B$16,2,FALSE) -> John | E17: East | F17: Books | G17: RmoCom | H17: 10 | I17: 120 | J17: 0 | K17: Alice | L17: Bank Transfer | M17: =H17 * I17 * (1 - J17) -> 1200 | N17: =TEXT(B17,"mmmm") -> February | O17: =TEXT(B17,"yyyy") -> 2023 | P17: =VLOOKUP(C17,customer!$A$1:$F$16,6,FALSE) -> Gold | Q17: =VLOOKUP(C17,customer!$A$1:$F$16,4,FALSE) -> 0 | R17: =CONCATENATE("Q",ROUNDUP(MONTH(B17)/3,0)," - ",YEAR(B17)) -> Q1 - 2023
A18: GM-0017 | B18: 44969 | C18: CUST-012 | D18: =VLOOKUP(C18,customer!$A$1:$B$16,2,FALSE) -> Alice | E18: North | F18: Food | G18: Jeans (Size 32) | H18: 1 | I18: 15 | J18: 0.1 | K18: David | L18: Credit Card | M18: =H18 * I18 * (1 - J18) -> 13.5 | N18: =TEXT(B18,"mmmm") -> February | O18: =TEXT(B18,"yyyy") -> 2023 | P18: =VLOOKUP(C18,customer!$A$1:$F$16,6,FALSE) -> Silver | Q18: =VLOOKUP(C18,customer!$A$1:$F$16,4,FALSE) -> 0 | R18: =CONCATENATE("Q",ROUNDUP(MONTH(B18)/3,0)," - ",YEAR(B18)) -> Q1 - 2023
A19: GM-0018 | B19: 44986 | C19: CUST-013 | D19: =VLOOKUP(C19,customer!$A$1:$B$16,2,FALSE) -> Charlie | E19: West | F19: Electronics | G19: Blender | H19: 2 | I19: 5 | J19: 0 | K19: Eve | L19: Cash | M19: =H19 * I19 * (1 - J19) -> 10 | N19: =TEXT(B19,"mmmm") -> March | O19: =TEXT(B19,"yyyy") -> 2023 | P19: =VLOOKUP(C19,customer!$A$1:$F$16,6,FALSE) -> Bronze | Q19: =VLOOKUP(C19,customer!$A$1:$F$16,4,FALSE) -> 0 | R19: =CONCATENATE("Q",ROUNDUP(MONTH(B19)/3,0)," - ",YEAR(B19)) -> Q1 - 2023
A20: GM-0019 | B20: 44990 | C20: CUST-014 | D20: =VLOOKUP(C20,customer!$A$1:$B$16,2,FALSE) -> David | E20: Central | F20: Apparel | G20: History Textbook | H20: 1 | I20: 99 | J20: 0 | K20: Bob | L20: UPI | M20: =H20 * I20 * (1 - J20) -> 99 | N20: =TEXT(B20,"mmmm") -> March | O20: =TEXT(B20,"yyyy") -> 2023 | P20: =VLOOKUP(C20,customer!$A$1:$F$16,6,FALSE) -> Platinum | Q20: =VLOOKUP(C20,customer!$A$1:$F$16,4,FALSE) -> 0 | R20: =CONCATENATE("Q",ROUNDUP(MONTH(B20)/3,0)," - ",YEAR(B20)) -> Q1 - 2023
A21: GM-0020 | B21: 44991 | C21: CUST-015 | D21: =VLOOKUP(C21,customer!$A$1:$B$16,2,FALSE) -> Emily | E21: South | F21: Home Goods | G21: Smartwatch | H21: 1 | I21: 60 | J21: 0.05 | K21: Charlie | L21: Credit Card | M21: =H21 * I21 * (1 - J21) -> 57 | N21: =TEXT(B21,"mmmm") -> March | O21: =TEXT(B21,"yyyy") -> 2023 | P21: =VLOOKUP(C21,customer!$A$1:$F$16,6,FALSE) -> Platinum | Q21: =VLOOKUP(C21,customer!$A$1:$F$16,4,FALSE) -> 0 | R21: =CONCATENATE("Q",ROUNDUP(MONTH(B21)/3,0)," - ",YEAR(B21)) -> Q1 - 2023
A22: GM-0021 | B22: 44992 | C22: CUST-003 | D22: =VLOOKUP(C22,customer!$A$1:$B$16,2,FALSE) -> David Lee | E22: East | F22: Books | G22: Gourmet Coffee | H22: 1 | I22: 70 | J22: 0 | K22: David | L22: Bank Transfer | M22: =H22 * I22 * (1 - J22) -> 70 | N22: =TEXT(B22,"mmmm") -> March | O22: =TEXT(B22,"yyyy") -> 2023 | P22: =VLOOKUP(C22,customer!$A$1:$F$16,6,FALSE) -> Silver | Q22: =VLOOKUP(C22,customer!$A$1:$F$16,4,FALSE) -> Lakeside | R22: =CONCATENATE("Q",ROUNDUP(MONTH(B22)/3,0)," - ",YEAR(B22)) -> Q1 - 2023
A23: GM-0022 | B23: 44993 | C23: CUST-002 | D23: =VLOOKUP(C23,customer!$A$1:$B$16,2,FALSE) -> Emily White | E23: West | F23: Electronics | G23: Winter Coat | H23: 2 | I23: 40 | J23: 0.15 | K23: Alice | L23: UPI | M23: =H23 * I23 * (1 - J23) -> 68 | N23: =TEXT(B23,"mmmm") -> March | O23: =TEXT(B23,"yyyy") -> 2023 | P23: =VLOOKUP(C23,customer!$A$1:$F$16,6,FALSE) -> Gold | Q23: =VLOOKUP(C23,customer!$A$1:$F$16,4,FALSE) -> Rivertown | R23: =CONCATENATE("Q",ROUNDUP(MONTH(B23)/3,0)," - ",YEAR(B23)) -> Q1 - 2023
A24: GM-0023 | B24: 44994 | C24: CUST-004 | D24: =VLOOKUP(C24,customer!$A$1:$B$16,2,FALSE) -> Michael Brown | E24: North | F24: Food | G24: Vacuum Cleaner | H24: 1 | I24: 250 | J24: 0 | K24: Bob | L24: Cash | M24: =H24 * I24 * (1 - J24) -> 250 | N24: =TEXT(B24,"mmmm") -> March | O24: =TEXT(B24,"yyyy") -> 2023 | P24: =VLOOKUP(C24,customer!$A$1:$F$16,6,FALSE) -> Bronze | Q24: =VLOOKUP(C24,customer!$A$1:$F$16,4,FALSE) -> Hillside | R24: =CONCATENATE("Q",ROUNDUP(MONTH(B24)/3,0)," - ",YEAR(B24)) -> Q1 - 2023
A25: GM-0024 | B25: 44995 | C25: CUST-015 | D25: =VLOOKUP(C25,customer!$A$1:$B$16,2,FALSE) -> Emily | E25: South | F25: Apparel | G25: Gaming Console | H25: 1 | I25: 20 | J25: 0 | K25: Charlie | L25: Credit Card | M25: =H25 * I25 * (1 - J25) -> 20 | N25: =TEXT(B25,"mmmm") -> March | O25: =TEXT(B25,"yyyy") -> 2023 | P25: =VLOOKUP(C25,customer!$A$1:$F$16,6,FALSE) -> Platinum | Q25: =VLOOKUP(C25,customer!$A$1:$F$16,4,FALSE) -> 0 | R25: =CONCATENATE("Q",ROUNDUP(MONTH(B25)/3,0)," - ",YEAR(B25)) -> Q1 - 2023
A26: GM-0025 | B26: 44967 | C26: CUST-013 | D26: =VLOOKUP(C26,customer!$A$1:$B$16,2,FALSE) -> Charlie | E26: East | F26: Home Goods | G26: Self-Help Guide | H26: 1 | I26: 150 | J26: 0 | K26: Eve | L26: Bank Transfer | M26: =H26 * I26 * (1 - J26) -> 150 | N26: =TEXT(B26,"mmmm") -> February | O26: =TEXT(B26,"yyyy") -> 2023 | P26: =VLOOKUP(C26,customer!$A$1:$F$16,6,FALSE) -> Bronze | Q26: =VLOOKUP(C26,customer!$A$1:$F$16,4,FALSE) -> 0 | R26: =CONCATENATE("Q",ROUNDUP(MONTH(B26)/3,0)," - ",YEAR(B26)) -> Q1 - 2023
A27: GM-0026 | B27: 44968 | C27: CUST-014 | D27: =VLOOKUP(C27,customer!$A$1:$B$16,2,FALSE) -> David | E27: West | F27: Apparel | G27: Summer wear | H27: 3 | I27: 300 | J27: 0.1 | K27: Alice | L27: Credit Card | M27: =H27 * I27 * (1 - J27) -> 810 | N27: =TEXT(B27,"mmmm") -> February | O27: =TEXT(B27,"yyyy") -> 2023 | P27: =VLOOKUP(C27,customer!$A$1:$F$16,6,FALSE) -> Platinum | Q27: =VLOOKUP(C27,customer!$A$1:$F$16,4,FALSE) -> 0 | R27: =CONCATENATE("Q",ROUNDUP(MONTH(B27)/3,0)," - ",YEAR(B27)) -> Q1 - 2023
A28: GM-0027 | B28: 44969 | C28: CUST-015 | D28: =VLOOKUP(C28,customer!$A$1:$B$16,2,FALSE) -> Emily | E28: North | F28: Home Goods | G28: Dispenser | H28: 6 | I28: 15 | J28: 0.05 | K28: Bob | L28: UPI | M28: =H28 * I28 * (1 - J28) -> 85.5 | N28: =TEXT(B28,"mmmm") -> February | O28: =TEXT(B28,"yyyy") -> 2023 | P28: =VLOOKUP(C28,customer!$A$1:$F$16,6,FALSE) -> Platinum | Q28: =VLOOKUP(C28,customer!$A$1:$F$16,4,FALSE) -> 0 | R28: =CONCATENATE("Q",ROUNDUP(MONTH(B28)/3,0)," - ",YEAR(B28)) -> Q1 - 2023
A29: GM-0028 | B29: 44970 | C29: CUST-005 | D29: =VLOOKUP(C29,customer!$A$1:$B$16,2,FALSE) -> Jessica Green | E29: South | F29: Books | G29: Sci-fi Novel | H29: 4 | I29: 5 | J29: 0 | K29: Eve | L29: Cash | M29: =H29 * I29 * (1 - J29) -> 20 | N29: =TEXT(B29,"mmmm") -> February | O29: =TEXT(B29,"yyyy") -> 2023 | P29: =VLOOKUP(C29,customer!$A$1:$F$16,6,FALSE) -> Gold | Q29: =VLOOKUP(C29,customer!$A$1:$F$16,4,FALSE) -> Centralia | R29: =CONCATENATE("Q",ROUNDUP(MONTH(B29)/3,0)," - ",YEAR(B29)) -> Q1 - 2023
A36: Products_discount
A37: ProductCategory | B37: Electronics | C37: Apparel | D37: Home Goods | E37: Books | F37: Food
A38: StandardDiscount | B38: 0.02 | C38: 0.03 | D38: 0.01 | E38: 0 | F38: 0.005

Sheet customer
A1: CustomerID | B1: CustomerName | C1: Email | D1: City | E1: State | F1: LoyaltyStatus | G1: FirstPurchaseDate
A2: CUST-001 | B2: Sarah Chen | C2: sarah.c@email.com | D2: Springfield | E2: Illinois | F2: Platinum | G2: 44691
A3: CUST-002 | B3: Emily White | C3: emily.w@email.com | D3: Rivertown | E3: New York | F3: Gold | G3: 44734
A4: CUST-003 | B4: David Lee | C4: david.l@email.com | D4: Lakeside | E4: Florida | F4: Silver | G4: 44743
A5: CUST-004 | B5: Michael Brown | C5: michael.b@email.com | D5: Hillside | E5: California | F5: Bronze | G5: 44788
A6: CUST-005 | B6: Jessica Green | C6: jessica.g@email.com | D6: Centralia | E6: Texas | F6: Gold | G6: 44807
A7: CUST-006 | B7: Chris Taylor | C7: chris.t@email.com | D7: Oceanview | E7: Florida | F7: Silver | G7: 44845
A8: CUST-007 | B8: Olivia Davis | C8: olivia.d@email.com | D8: Metroville | E8: New York | F8: Bronze | G8: 44885
A9: CUST-008 | B9: Liam Wilson | C9: liam.w@email.com | D9: Springfield | E9: Illinois | F9: Platinum | G9: 44900
A10: CUST-009 | B10: Sophia Miller | C10: sophia.m@email.com | D10: Rivertown | E10: New York | F10: Silver | G10: 44927
A11: CUST-010 | B11: Noah Garcia | C11: noah.g@email.com | D11: Lakeside | E11: Florida | F11: Gold | G11: 44936
A12: CUST-011 | B12: John | C12: =CONCATENATE(B12,".124@gmail.com") -> John.124@gmail.com | E12: London | F12: Gold | G12: 44937
A13: CUST-012 | B13: Alice | C13: =CONCATENATE(B13,".124@gmail.com") -> Alice.124@gmail.com | E13: Seattle | F13: Silver | G13: 44938
A14: CUST-013 | B14: Charlie | C14: =CONCATENATE(B14,".124@gmail.com") -> Charlie.124@gmail.com | E14: Bali | F14: Bronze | G14: 44939
A15: CUST-014 | B15: David | C15: =CONCATENATE(B15,".124@gmail.com") -> David.124@gmail.com | E15: Florida | F15: Platinum | G15: 44940
A16: CUST-015 | B16: Emily | C16: =CONCATENATE(B16,".124@gmail.com") -> Emily.124@gmail.com | E16: New York | F16: Platinum | G16: 44941

Sheet case study
A1: Case Study: GlobalMart Sales & Customer Analysis Scenario: You are a Business Analyst at "GlobalMart," a large retail company. Your management has provided you with two datasets: Sales Data (detailing individual transactions) and Customer Data (containing information about GlobalMart's registered customers). Your task is to analyze this data to gain insights into sales performance, customer behavior, and regional trends.
A16: Calculate Net Sales Amount: In the Sales Data sheet, add a new column called Net Sales Amount. This should be UnitsSold * UnitPrice * (1 - Discount).
A17: Order Month: In the Sales Data sheet, add a new column called OrderMonth. Extract the month name (e.g., "January", "February") from the OrderDate.
A18: Order Year: In the Sales Data sheet, add a new column called OrderYear. Extract the year (e.g., "2023") from the OrderDate.
A19: Total Units Sold: What is the total number of Units Sold across all transactions? | H19: =SUM(sales!H2:H29) -> 68
A20: Average Unit Price: What is the average UnitPrice of all products sold? | H20: =AVERAGE(sales!I2:I29) -> 127.53571
A21: Highest Sales Amount: What was the single highest Net Sales Amount for any transaction? | H21: =MAX(sales!M2:M29) -> 1615
A22: Number of Transactions: How many total transactions are recorded in the Sales Data? | H22: =COUNTA(sales!A2:A29) -> 28
A23: Expensive Orders: How many orders had a Net Sales Amount greater than $200? | H23: =COUNTIF(sales!M2:M29,">200") -> 7
A25: Customer Loyalty Status in Sales Data (VLOOKUP/XLOOKUP): In the Sales Data sheet, add a new column called CustomerLoyaltyStatus. Use CustomerID to look up the LoyaltyStatus from the Customer Data sheet and bring it into the Sales Data sheet. (Hint: Use VLOOKUP or XLOOKUP).
A26: Customer City in Sales Data (VLOOKUP/XLOOKUP): Similar to Q9, add a new column CustomerCity in Sales Data and populate it using CustomerID to get the City from Customer Data.
A27: Find Specific Customer Email (INDEX/MATCH or XLOOKUP): If you know CustomerName "Michael Brown", what is their Email address from the Customer Data sheet? (Hint: Use INDEX/MATCH or XLOOKUP). | O27: =INDEX(customer!$C$1:$C$16,MATCH(customer!B5,customer!$B$1:$B$16,0)) -> michael.b@email.com
A28: Product Category Discount (HLOOKUP - Requires a small lookup table): Create a small separate table (e.g., on a new sheet or to the side of your Sales Data sheet) that maps ProductCategory to a StandardDiscount (e.g., Electronics: 0.02, Apparel: 0.03, Home Goods: 0.01, Books: 0.00, Food: 0.005). Use HLOOKUP to find the StandardDiscount for "Apparel". (Note: This is a more contrived HLOOKUP example as data is usually vertical)
A29: =HLOOKUP("Apparel",sales!$A$37:$F$38,2,0) -> 0.03
A30: Total Sales by Salesperson: Create a Pivot Table to show the Sum of Net Sales Amount for each Salesperson.
A31: Total Sales by Region and Product Category: Create a Pivot Table that shows the Sum of Net Sales Amount, with Region as rows and ProductCategory as columns.
A32: Average Sales per Payment Method: Create a Pivot Table to show the Average of Net Sales Amount for each PaymentMethod.
A33: Units Sold by Month and Product Category: Create a Pivot Table showing the Sum of Units Sold, with OrderMonth as rows and ProductCategory as columns.
A34: Top 5 Products by Sales Amount: Create a Pivot Table showing Sum of Net Sales Amount by ProductName. Then, apply a filter to show only the Top 5 products by sales.
A35: Sales Trend by Quarter: Create a Pivot Table showing Sum of Net Sales Amount by OrderDate. Then, group the OrderDate field by Quarters and Years.
A36: Customer Loyalty Status Sales Contribution: Create a Pivot Table showing the Sum of Net Sales Amount for each CustomerLoyaltyStatus.
A37: Count of Orders by Salesperson and Payment Method: Create a Pivot Table to count the number of OrderIDs (or any non-numeric field) for each Salesperson and PaymentMethod.
A39: Total Sales by Salesperson | D39: Average Sales per Payment Method | G39: Top 5 Products by Sales Amount | K39: Count of Orders by Salesperson and Payment Method
A40: Row Labels | B40: Sum of NeT Sales | D40: Row Labels | E40: Average of NeT Sales | G40: Row Labels | H40: Sum of NeT Sales | K40: Count of OrderID | L40: Column Labels
A41: Alice | B41: 4388 | D41: Bank Transfer | E41: 298.33333 | G41: Gaming Console | H41: 420 | K41: Row Labels | L41: Bank Transfer | M41: Cash | N41: Credit Card | O41: UPI | P41: Grand Total
A42: Bob | B42: 755.5 | D42: Cash | E42: 89.841667 | G42: Laptop Pro | H42: 1615 | K42: Alice | L42: 2 | N42: 3 | O42: 2 | P42: 7
A43: Charlie | B43: 379.5 | D43: Credit Card | E43: 351.11111 | G43: RmoCom | H43: 1200 | K43: Bob | M43: 3 | O43: 4 | P43: 7
A44: David | B44: 173.5 | D44: UPI | E44: 109.5 | G44: Summer wear | H44: 810 | K44: Charlie | N44: 4 | O44: 1 | P44: 5
A45: Eve | B45: 559.05 | D45: Grand Total | E45: 223.4125 | G45: Vacuum Cleaner | H45: 535 | K45: David | L45: 2 | N45: 2 | P45: 4
A46: Grand Total | B46: 6255.55 | G46: Grand Total | H46: 4580 | K46: Eve | L46: 2 | M46: 3 | P46: 5
D47: Units Sold by Month and Product Category | K47: Grand Total | L47: 6 | M47: 6 | N47: 9 | O47: 7 | P47: 28
A48: Total Sales by Region and Product Category | G48: Sales Trend by Quarter
A49: Row Labels | B49: Sum of NeT Sales | D49: Row Labels | E49: Sum of UnitsSold | G49: Row Labels | H49: Sum of NeT Sales
A50: Central | B50: 478.05 | D50: January | E50: 8 | G50: Q1 - 2023 | H50: 5534.55
A51: Apparel | B51: 99 | D51: Apparel | E51: 5 | G51: Q2 - 2023 | H51: 721
A52: Electronics | B52: 94.05 | D52: Electronics | E52: 2 | G52: Grand Total | H52: 6255.55
A53: Home Goods | B53: 285 | D53: Home Goods | E53: 1
A54: East | B54: 1722.5 | D54: February | E54: 41 | G54: Customer Loyalty Status Sales
A55: Apparel | B55: 135 | D55: Apparel | E55: 5 | G55: Row Labels | H55: Sum of NeT Sales
A56: Books | B56: 1270 | D56: Books | E56: 17 | G56: Bronze | H56: 0.10150986
...
